Workbook

Sheet LÉEME
B1: MONIFIC × BNO — Matriz única de hallazgos (documento de trabajo)
B2: 4 auditorías + dictamen de BNO + validación Monific (Raquel) + estado de TI (Daniel)
B3: Corte: 18-jun-2026 · Portal HubSpot 48427391 · 284 hallazgos de auditoría + 81 comunicaciones TO BE · Corte oficial: 251 abiertos = 217 exigibles a BNO (84 críticos, 87 altos, 37 medios, 9 bajos) + 2 controles informativos + 32 no exigidos.
B5: QUÉ ES ESTE ARCHIVO
B6: Una sola fuente de verdad para el cierre con BNO: reúne en la hoja «Hallazgos consolidados» todo lo detectado en las 4 auditorías, con qué dijo BNO, qué falta validar Monific y qué ya resolvió TI (Monific).
B8: FUENTES (columna «Origen»)
B9: • 1ª Auditoría (+ dictamen BNO): 112 hallazgos. Se usa la versión «Comentarios BNO» = la 1ª con la columna de dictamen de BNO llena.
B10: • 2ª Auditoría: 109 registros de re-validación; donde aplica indica qué fila de la 1ª pasada actualiza.
B11: • 3ª Bitácora técnica: 57 hallazgos APP-001 a APP-057 (API / propiedades / apps privadas).
B12: • 4ª Auditoría de Comunicaciones: AS-IS van en «Hallazgos consolidados»; las 81 comunicaciones (0 implementadas) viven en su pestaña «Comunicaciones (81)».
B13: Evidencia Auditoría API HubSpot (17-jun-2026): Se realizó una extracción directamente desde HubSpot para documentar el estado real de la cuenta, sin depender de interpretaciones manuales ni de información declarada por BNO. La evidencia está concentrada en las pestañas «WF estado real (96)», «Verificación 31 propiedades», «Auditoría API 17-jun», «WF lógica (detalle API)» y «Acceso y config (API)». Esta auditoría confirma, con datos obtenidos directamente por API, los siguientes puntos: Workflows apagados: se identificó el estado real de los 96 workflows existentes. Propiedades no creadas por BNO: se verificó cuáles de las 31 propiedades comprometidas no existen en HubSpot. Objeto de Cobranza inexistente: se confirmó que el objeto personalizado de Cobranza no fue creado. Accesos activos no regularizados: aún existen usuarios de BNO y usuarios externos con acceso a la cuenta. Lógica interna auditada: además del estado general, se revisó la lógica interna de los 96 workflows, con un total de 4,848 nodos verificados.
B15: COLUMNAS DE CONTROL
... B31: Aclaración de autoría: los masters de implementación y los flujogramas yson entregables de BNO derivados del discovery contratado (Add-On Mapeo de Procesos), NO insumos de Monific. Monific solo participó, revisó, autorizó y corrigió; su elaboración y depuración son responsabilidad de BNO.

Sheet Tablero
B1: MONIFIC × BNO — Tablero de cierre (en vivo)
B2: Se actualiza solo conforme marcas la validación y cambian los estatus de TI y de comunicaciones.
B4: Indicador | C4: Avance | D4: % | E4: Barra
B5: Hallazgos en seguimiento — abiertos (en vivo) | C5: =(COUNTIF('Hallazgos consolidados'!$N$2:$N$5000,"Sigue mal (abierto)")+COUNTIF('Hallazgos consolidados'!$N$2:$N$5000,"Sigue mal — BNO reconoció que aplica")+COUNTIF('Hallazgos consolidados'!$N$2:$N$5000,"Sigue mal — verificado por API")+COUNTIF('Hallazgos consolidados'!$N$2:$N$5000,"BNO documentó resuelto pero sigue mal")+COUNTIF('Hallazgos consolidados'!$N$2:$N$5000,"Bloqueado — pendiente decisión Monific")+COUNTIF('Hallazgos consolidados'!$N$2:$N$5000,"En curso (BNO)")+COUNTIF('Hallazgos consolidados'!$N$2:$N$5000,"Pendiente — BNO debe definir")+COUNTIF('Hallazgos consolidados'!$N$2:$N$5000,"Pendiente — TI Monific"))&" / "&COUNTA('Hallazgos consolidados'!$A$2:$A$5000) -> 249 / 284 | D5: =IFERROR((COUNTIF('Hallazgos consolidados'!$N$2:$N$5000,"Sigue mal (abierto)")+COUNTIF('Hallazgos consolidados'!$N$2:$N$5000,"Sigue mal — BNO reconoció que aplica")+COUNTIF('Hallazgos consolidados'!$N$2:$N$5000,"Sigue mal — verificado por API")+COUNTIF('Hallazgos consolidados'!$N$2:$N$5000,"BNO documentó resuelto pero sigue mal")+COUNTIF('Hallazgos consolidados'!$N$2:$N$5000,"Bloqueado — pendiente decisión Monific")+COUNTIF('Hallazgos consolidados'!$N$2:$N$5000,"En curso (BNO)")+COUNTIF('Hallazgos consolidados'!$N$2:$N$5000,"Pendiente — BNO debe definir")+COUNTIF('Hallazgos consolidados'!$N$2:$N$5000,"Pendiente — TI Monific"))/COUNTA('Hallazgos consolidados'!$A$2:$A$5000),0) -> 0.87676056 | E5: =REPT("█",MAX(0,MIN(20,ROUND(D5*20,0))))&REPT("░",20-MAX(0,MIN(20,ROUND(D5*20,0)))) -> ██████████████████░░
B6: Hallazgos resueltos o validados | C6: =(COUNTIF('Hallazgos consolidados'!$N$2:$N$5000,"Validado (resuelto)")+COUNTIF('Hallazgos consolidados'!$N$2:$N$5000,"Resuelto (con pendiente menor)")+COUNTIF('Hallazgos consolidados'!$N$2:$N$5000,"Resuelto pendiente de confirmar")+COUNTIF('Hallazgos consolidados'!$N$2:$N$5000,"Resuelto por TI Monific (Daniel)"))&" / "&COUNTA('Hallazgos consolidados'!$A$2:$A$5000) -> 18 / 284 | D6: =IFERROR((COUNTIF('Hallazgos consolidados'!$N$2:$N$5000,"Validado (resuelto)")+COUNTIF('Hallazgos consolidados'!$N$2:$N$5000,"Resuelto (con pendiente menor)")+COUNTIF('Hallazgos consolidados'!$N$2:$N$5000,"Resuelto pendiente de confirmar")+COUNTIF('Hallazgos consolidados'!$N$2:$N$5000,"Resuelto por TI Monific (Daniel)"))/COUNTA('Hallazgos consolidados'!$A$2:$A$5000),0) -> 0.063380282 | E6: =REPT("█",MAX(0,MIN(20,ROUND(D6*20,0))))&REPT("░",20-MAX(0,MIN(20,ROUND(D6*20,0)))) -> █░░░░░░░░░░░░░░░░░░░
B7: Defectos que BNO reconoció y siguen abiertos | C7: =COUNTIF('Hallazgos consolidados'!$N$2:$N$5000,"Sigue mal — BNO reconoció que aplica")&" / "&COUNTA('Hallazgos consolidados'!$A$2:$A$5000) -> 103 / 284 | D7: =IFERROR(COUNTIF('Hallazgos consolidados'!$N$2:$N$5000,"Sigue mal — BNO reconoció que aplica")/COUNTA('Hallazgos consolidados'!$A$2:$A$5000),0) -> 0.36267606 | E7: =REPT("█",MAX(0,MIN(20,ROUND(D7*20,0))))&REPT("░",20-MAX(0,MIN(20,ROUND(D7*20,0)))) -> ███████░░░░░░░░░░░░░
B8: Acciones de TI (Daniel) cerradas | C8: =COUNTIF('Hallazgos consolidados'!$O$2:$O$5000,"Sí – Daniel (hecho)")&" / "&(COUNTIF('Hallazgos consolidados'!$O$2:$O$5000,"Sí – Daniel (hecho)")+COUNTIF('Hallazgos consolidados'!$O$2:$O$5000,"Pendiente TI")+COUNTIF('Hallazgos consolidados'!$O$2:$O$5000,"Condicionado a BNO")) -> 12 / 20 | D8: =IFERROR(COUNTIF('Hallazgos consolidados'!$O$2:$O$5000,"Sí – Daniel (hecho)")/(COUNTIF('Hallazgos consolidados'!$O$2:$O$5000,"Sí – Daniel (hecho)")+COUNTIF('Hallazgos consolidados'!$O$2:$O$5000,"Pendiente TI")+COUNTIF('Hallazgos consolidados'!$O$2:$O$5000,"Condicionado a BNO")),0) -> 0.6 | E8: =REPT("█",MAX(0,MIN(20,ROUND(D8*20,0))))&REPT("░",20-MAX(0,MIN(20,ROUND(D8*20,0)))) -> ████████████░░░░░░░░
B9: Comunicaciones construidas (de 81) | C9: =(COUNTA('Comunicaciones (81)'!$A$2:$A$5000)-COUNTIF('Comunicaciones (81)'!$L$2:$L$5000,"No iniciado"))&" / "&COUNTA('Comunicaciones (81)'!$A$2:$A$5000) -> 0 / 81 | D9: =IFERROR((COUNTA('Comunicaciones (81)'!$A$2:$A$5000)-COUNTIF('Comunicaciones (81)'!$L$2:$L$5000,"No iniciado"))/COUNTA('Comunicaciones (81)'!$A$2:$A$5000),0) -> 0 | E9: =REPT("█",MAX(0,MIN(20,ROUND(D9*20,0))))&REPT("░",20-MAX(0,MIN(20,ROUND(D9*20,0)))) -> ░░░░░░░░░░░░░░░░░░░░
B11: Contexto (no es %) | C11: Valor
B12: Pendientes exigibles a BNO (corte del requerimiento) | C12: =COUNTIF('Hallazgos consolidados'!$W$2:$W$5000,"Sí") -> 217
B13: — de ellos, críticos exigibles a BNO | C13: =COUNTIFS('Hallazgos consolidados'!$W$2:$W$5000,"Sí",'Hallazgos consolidados'!$I$2:$I$5000,"Crítico") -> 84
B14: Total hallazgos / comunicaciones | C14: =COUNTA('Hallazgos consolidados'!$A$2:$A$5000)&" / "&COUNTA('Comunicaciones (81)'!$A$2:$A$5000) -> 284 / 81
B15: Conciliación del corte oficial: 284 = 18 resueltos + 15 descartados + 251 abiertos. Los 251 abiertos = 217 exigibles a BNO + 2 controles informativos (CON-216/217) + 32 no exigidos directamente a BNO. Críticos exigibles a BNO: 84 (87 altos, 37 medios, 9 bajos). Las barras de arriba son seguimiento operativo en vivo y pueden variar mientras Raquel valida cada fila.
B16: Qué estado de validación mueve qué (para que sepas el efecto al cambiar una fila):
B17: • Suma a «Siguen mal / abiertos»: Sigue mal (abierto), Sigue mal — BNO reconoció que aplica, Sigue mal — verificado por API, BNO documentó resuelto pero sigue mal, Bloqueado — pendiente decisión Monific, En curso (BNO), Pendiente — BNO debe definir, Pendiente — TI Monific
B18: • Suma a «Resueltos / validados»: Validado (resuelto), Resuelto (con pendiente menor), Resuelto pendiente de confirmar, Resuelto por TI Monific (Daniel)
B19: • Neutrales (no mueven ninguna barra): Descartado por acuerdo de alcance (revisar), No aplica / informativo, Sin evidencia objetiva — revisar
B21: Cómo leerlo: las barras y % suben solos al cambiar la columna «Validación Monific (Raquel)» o los estatus. Edita en Excel o Google Sheets (no en PDF).
B23: Estado real en HubSpot (API · 17-jun-2026) — snapshot, no cambia solo | C23: Avance | D23: % | E23: Barra
B24: Workflows activos (ON) en HubSpot | C24: =COUNTIF('WF estado real (96)'!$C$2:$C$5000,"ON")&" / "&COUNTA('WF estado real (96)'!$A$2:$A$5000) -> 57 / 96 | D24: =IFERROR(COUNTIF('WF estado real (96)'!$C$2:$C$5000,"ON")/COUNTA('WF estado real (96)'!$A$2:$A$5000),0) -> 0.59375 | E24: =REPT("█",MAX(0,MIN(20,ROUND(D24*20,0))))&REPT("░",20-MAX(0,MIN(20,ROUND(D24*20,0)))) -> ████████████░░░░░░░░
B25: Propiedades de las 31 de BNO creadas | C25: =COUNTIF('Verificación 31 propiedades'!$H$2:$H$5000,"EXISTE*")&" / 31" -> 5 / 31 | D25: =IFERROR(COUNTIF('Verificación 31 propiedades'!$H$2:$H$5000,"EXISTE*")/31,0) -> 0.16129032 | E25: =REPT("█",MAX(0,MIN(20,ROUND(D25*20,0))))&REPT("░",20-MAX(0,MIN(20,ROUND(D25*20,0)))) -> ███░░░░░░░░░░░░░░░░░
B26: Workflows que comunican al cliente (de 96) | C26: =9&" / 96" -> 9 / 96 | D26: =IFERROR(9/96,0) -> 0.09375 | E26: =REPT("█",MAX(0,MIN(20,ROUND(D26*20,0))))&REPT("░",20-MAX(0,MIN(20,ROUND(D26*20,0)))) -> ██░░░░░░░░░░░░░░░░░░

Sheet Hallazgos consolidados
A1: ID | B1: Origen | C1: ID origen | D1: Tipo de registro | E1: Proceso / Pipeline | F1: WF | G1: Hallazgo | H1: Severidad (orig.) | I1: Prioridad (norm.) | J1: Estado (según auditoría) | K1: Responsable (según auditoría) | L1: Quién debe actuar (norm.) | M1: Dictamen / Comentario de BNO | N1: Validación Monific (Raquel) | O1: Resuelto por TI (Daniel) | P1: Ref. punto TI | Q1: Acción correctiva / propuesta | R1: Evidencia | S1: Notas / vínculo | T1: Sustento de validación | U1: Fecha detección (auditoría) | V1: Fecha validación Monific | W1: Exigible BNO (canónico)
A2: CON-001 | B2: 1ª Auditoría (+ dictamen BNO) | C2: WF-001 · f1 | D2: Hallazgo base | F2: WF-001 | G2: La carpeta Drive del solicitante se crea 100% manual por el asesor. La integración HubSpot↔Drive (marzo 2026) no se está usando, así que se pierde la automatización. | H2: Alto | I2: Alto | J2: Abierto | K2: BNO – Implementación | L2: BNO | M2: Sesión 19-may NO aplicado: la integración nativa no replica plantillas con estructura. Solución: Apps Script externo. Reasignado a BNO/Tech Monific. | N2: BNO documentó resuelto pero sigue mal | O2: No aplica | Q2: Ver posibilidad de usar la acción nativa 'Crear carpeta' de la integración, o un webhook a Apps Script, para que la carpeta se cree sola con nomenclatura estándar, permisos por rol y URL persistida en el Negocio. La tarea al asesor debería ser solo enviar el link. | S2: Master de Implementación_ Proceso Comercial - Monific | T2: BNO documentó acción pero quedó NO aplicado; auditoría: Abierto | U2: 2026-05-18 | V2: 46191 | W2: Sí
A3: CON-002 | B3: 1ª Auditoría (+ dictamen BNO) | C3: WF-001 · f2 | D3: Hallazgo base | F3: WF-001 | G3: La tarea creada al asesor tenía vencimiento a 5 días laborables y recordatorio al día 3, pero NO había paso de escalamiento si la tarea no se completaba. | H3: Alto | I3: Alto | J3: Resuelto | K3: BNO – Implementación | L3: BNO | M3: APLICADO: se agregaron al WF-001 las acciones de retraso 6 días laborables + ramificación 'Estado de tarea ≠ Terminada' + email de escalamiento a Karen Gómez. Sin reasignación de ownership porque Karen | N3: Validado (resuelto) | O3: No aplica | Q3: Crear WF de escalamiento que detecte la tarea vencida al día 5+1 y notifique al superior (Karen) por email, además de reasignar la tarea. | S3: Master de Implementación_ Proceso Comercial - Monific | T3: Auditoría: Resuelto y aplicado | U3: 2026-05-18 | V3: 46191 | W3: No
A4: CON-003 | B4: 1ª Auditoría (+ dictamen BNO) | C4: WF-001 · f3 | D4: Hallazgo base | F4: WF-001 | G4: Los vencimientos y recordatorios de tareas se calculaban en UTC-04, pero Monific opera en CDMX (UTC-06). Resultado: las tareas se disparaban con 2 horas de desfase respecto al día laboral mexicano. | H4: Medio | I4: Medio | J4: Resuelto | K4: BNO – Arquitectura | L4: BNO | M4: APLICADO. Zona horaria cambiada a UTC-06 CDMX y persistida tras recarga. Pendiente: BNO revisar WFs Solicitantes que leen horarios fijos. | N4: Resuelto (con pendiente menor) | O4: No aplica | Q4: Cambiar zona horaria de la cuenta HubSpot a America/Mexico_City (UTC-06). Validar que todos los WFs que leen '8:00' o '9:00' sigan teniendo sentido en CDMX. | S4: Master de Implementación_ Proceso Comercial - Monific | T4: Auditoría: Resuelto, con pendiente menor en el dictamen | U4: 2026-05-18 | V4: 46191 | W4: No
A5: CON-004 | B5: 1ª Auditoría (+ dictamen BNO) | C5: WF-002 · f4 | D5: Hallazgo base | F5: WF-002 | G5: El WF mueve el negocio de Nuevo a Evaluación sin dejar registro de quién/cuándo. | H5: Medio | I5: Medio | J5: Descartado | K5: Monific – Raquel | L5: Monific – negocio (Raquel) | M5: Validado por BNO. Se mantiene descartado para MVP por decisión de alcance. Aunque la trazabilidad es recomendable, Monific decidió no incorporarlo en esta etapa. | N5: Descartado por acuerdo de alcance (revisar) | O5: No aplica | Q5: Agregar acciones que escriban 'Fecha de entrada a Evaluación' y 'Origen del cambio = Automático WF-002' antes del cambio de etapa. | S5: Master de Implementación_ Proceso Comercial - Monific | T5: Auditoría: Descartado (decisión de alcance/MVP) — revisar si Monific lo acepta | U5: 2026-05-18 | V5: 46191 | W5: No
A6: CON-005 | B6: 1ª Auditoría (+ dictamen BNO) | C6: WF-002 · f5 | D6: Hallazgo base | F6: WF-002 | G6: Reinscripción apagada. Si un solicitante fue rechazado y se devuelve a Nuevo para retrabajo, al volver a tener documentación completa NO se mueve automáticamente a Evaluación, queda atorado y obliga al asesor a moverlo a mano. | H6: Medio | I6: Medio | J6: Bloqueado | K6: Monific – Raquel | L6: Monific – negocio (Raquel) | M6: Validado por BNO. Se mantiene bloqueado/pendiente de decisión Comercial. Si Monific decide automatizar reingresos a Nuevo, se debe activar reinscripción con condiciones acotadas para evitar movimientos duplicados. | N6: Bloqueado — pendiente decisión Monific | O6: No aplica | Q6: Decidir con Comercial si se quiere reinscripción automática al re-entrar a Nuevo con documentación completa. Si sí, activar reinscripción. | S6: Master de Implementación_ Proceso Comercial - Monific | T6: Auditoría: Bloqueado; BNO lo dejó a decisión de Monific | U6: 2026-05-18 | V6: 46191 | W6: No
A7: CON-006 | B7: 1ª Auditoría (+ dictamen BNO) | C7: WF-003 · f6 | D7: Hallazgo base | F7: WF-003 | G7: Cuando un solicitante entra a Nuevo con documentación ya completa, WF-002 y WF-003 se disparan en paralelo: uno lo mueve a Evaluación, el otro lo pone En pausa y lo inscribe en secuencia. Resultado: estado inconsistente. | H7: Alto | I7: Alto | J7: Abierto | K7: BNO – Implementación | L7: BNO | M7: Validado por BNO. El hallazgo aplica: WF-002 y WF-003 deben quedar mutuamente excluyentes para evitar estados inconsistentes. Ajustar condición de WF-003 para excluir documentación completa y probar caso de ingreso con documentación completa. | N7: Sigue mal — BNO reconoció que aplica | O7: No aplica | Q7: Agregar al WF-003 la condición 'Estatus de documentación NO es Completa' para que ambos WFs sean mutuamente excluyentes. | S7: Master de Implementación_ Proceso Comercial - Monific | T7: Auditoría: Abierto; BNO validó por escrito que el hallazgo APLICA | U7: 2026-05-18 | V7: 46191 | W7: Sí
A8: CON-007 | B8: 1ª Auditoría (+ dictamen BNO) | C8: WF-003 · f7 | D8: Hallazgo base | F8: WF-003 | G8: El WF marca la bandera 'Inscribir en secuencia +15 días' sobre TODOS los contactos asociados al negocio. Si el negocio tiene varios contactos (solicitante + asesor interno + apoderado), todos reciben la secuencia diseñada para el solicitante. | H8: Medio | I8: Medio | J8: Abierto | K8: BNO – Implementación | L8: BNO | M8: Validado por BNO. Aplica como ajuste de seguridad operativa. Se debe filtrar la actualización de bandera solo al rol de contacto correspondiente y excluir contactos internos antes de activar/usar la secuencia. | N8: Sigue mal — BNO reconoció que aplica | O8: No aplica | Q8: Filtrar por rol = 'Solicitante principal' antes de actualizar la propiedad. Validar que la secuencia también excluya dominios internos @monific.com. | S8: Master de Implementación_ Proceso Comercial - Monific | T8: Auditoría: Abierto; BNO validó por escrito que el hallazgo APLICA | U8: 2026-05-18 | V8: 46191 | W8: Sí
A9: CON-008 | B9: 1ª Auditoría (+ dictamen BNO) | C9: WF-003 · f8 | D9: Hallazgo base | F9: WF-003 | G9: Reinscripción apagada. Si un negocio retrocede a Nuevo (después de un rechazo temporal), no se re-pausa documentación ni se re-inscribe al contacto. Hay que ejecutar el ciclo a mano. | H9: Medio | I9: Medio | J9: Descartado | K9: Monific – Raquel | L9: Monific – negocio (Raquel) | M9: Validado por BNO. Se descarta para MVP por volumen actual y baja frecuencia esperada del caso. Mantener como mejora futura si aumentan reingresos o retrabajos en etapa Nuevo. | N9: Descartado por acuerdo de alcance (revisar) | O9: No aplica | Q9: Decidir con Comercial si re-procesar automáticamente al retroceso de etapa. Si sí, activar reinscripción. | S9: Master de Implementación_ Proceso Comercial - Monific | T9: Auditoría: Descartado (decisión de alcance/MVP) — revisar si Monific lo acepta | U9: 2026-05-18 | V9: 46191 | W9: No
A10: CON-009 | B10: 1ª Auditoría (+ dictamen BNO) | C10: WF-004 · f9 | D10: Hallazgo base | F10: WF-004 | G10: El WF está APAGADO. WF-003 marca la bandera para inscribir en secuencia de +15 días, pero como WF-004 está apagado, nadie ejecuta la inscripción. El ciclo de seguimiento al solicitante a 15 días queda roto. | H10: Alto | I10: Alto | J10: En curso | K10: BNO + Monific | L10: Compartido (BNO + Monific) | M10: Validado por BNO. En curso. La plantilla ya fue trabajada; queda pendiente validar aprobación final de contenido/remitente y activar WF-004 solo después de una prueba punta a punta con contacto de prueba. | N10: En curso (BNO) | O10: No aplica | Q10: Validar contenido del correo de la secuencia con Marketing/Comercial (asunto, body, opt-out, footer legal CNBV). Una vez aprobado, activar WF-004. | S10: Master de Implementación_ Proceso Comercial - Monific | T10: Auditoría/BNO: en curso, sin entregar | U10: 2026-05-18 | V10: 46191 | W10: Sí
A11: CON-010 | B11: 1ª Auditoría (+ dictamen BNO) | C11: WF-004 · f10 | D11: Hallazgo base | F11: WF-004 | G11: El nombre del WF en HubSpot es '...+15 días | V1' pero el master lo registra como 'Enviar secuencia desde contacto' (sin '+15 días'). Mismo tipo de desincronización en WF-021. Genera confusión | H11: Medio | I11: Medio | J11: Abierto | K11: BNO – Implementación | L11: BNO | M11: Validado por BNO. Aplica como limpieza de gobierno del proyecto. Se recomienda homologar el nombre del WF entre HubSpot y master para evitar confusión en soporte, auditoría y capacitación. | N11: Sigue mal — BNO reconoció que aplica | O11: No aplica | Q11: Decidir nomenclatura oficial y sincronizar. Recomendado: usar el nombre de HubSpot como fuente única y actualizar el master. | S11: Master de Implementación_ Proceso Comercial - Monific | T11: Auditoría: Abierto; BNO validó por escrito que el hallazgo APLICA | U11: 2026-05-18 | V11: 46191 | W11: Sí
A12: CON-011 | B12: 1ª Auditoría (+ dictamen BNO) | C12: WF-004 · f11 | D12: Hallazgo base | F12: WF-004 | G12: La inscripción a la secuencia se hace en nombre del 'Propietario del contacto'. Si el contacto no tiene propietario (caso común cuando entra por formulario), la inscripción falla. | H12: Medio | I12: Medio | J12: Abierto | K12: BNO – Implementación | L12: BNO | M12: Validado por BNO. Aplica parcialmente: la lógica de inscripción es correcta, pero requiere fallback de propietario/remitente. Definir si el remitente estándar será solicitantes@monific.com y ajustar antes de activar. | N12: Sigue mal — BNO reconoció que aplica | O12: No aplica | Q12: Agregar paso previo: si Propietario está vacío, asignar a solicitantes@monific.com (buzón compartido) y luego inscribir. | S12: Master de Implementación_ Proceso Comercial - Monific | T12: Auditoría: Abierto; BNO validó por escrito que el hallazgo APLICA | U12: 2026-05-18 | V12: 46191 | W12: Sí
A13: CON-012 | B13: 1ª Auditoría (+ dictamen BNO) | C13: WF-005 · f12 | D13: Hallazgo base | F13: WF-005 | G13: WF-002, WF-003 y WF-005 disparan todos en la misma etapa Nuevo. WF-003 y WF-005 se ejecutan en paralelo y setean banderas para secuencias distintas (+15d y +2d) sobre los mismos contactos → posible doble correo al solicitante. | H13: Alto | I13: Alto | J13: Abierto | K13: BNO – Implementación | L13: BNO | M13: Validado por BNO. Aplica como conflicto de diseño. Recomendamos consolidar el seguimiento de documentación en una sola lógica con delays internos o segmentar por antigüedad del negocio para evitar doble contacto. | N13: Sigue mal — BNO reconoció que aplica | O13: No aplica | Q13: Diferenciar con condiciones temporales: WF-005 con 'Negocio creado hace <2 días' y WF-003 con 'Negocio creado hace >=14 días'. O consolidar ambos en un solo WF con delays internos. | S13: Master de Implementación_ Proceso Comercial - Monific | T13: Auditoría: Abierto; BNO validó por escrito que el hallazgo APLICA | U13: 2026-05-18 | V13: 46191 | W13: Sí
... A113: CON-112 | B113: 1ª Auditoría (+ dictamen BNO) | C113: WF-062 · f112 | D113: Hallazgo base | F113: WF-062 | G113: PATRÓN SISTÉMICO en las 3 etapas terminales CNBV (Cierre Refi, Liquidada, Incumplimiento): los WFs de 'propiedades de entrada' son insuficientes. WF-062 solo setea 1 propiedad. WF-063 setea 4 propiedades trazables pero CERO notificaciones. WF-064 tiene notif pero solo a Raquel hardcoded. Las tres son reportables a CNBV y requieren: notificación consistente por rol, propiedades trazables completas, registro CNBV. La inconsistencia revela falta de template/SOP de cierre regulatorio. | H113: Crítico | I113: Crítico | J113: Abierto | K113: BNO + Monific | L113: Compartido (BNO + Monific) | M113: Validado por BNO. Aplica como patrón sistémico. Crear template/SOP único de cierre regulatorio CNBV para Refi, Liquidada e Incumplimiento con propiedades, notificaciones, registro y archivo. | N113: Sigue mal — BNO reconoció que aplica | O113: No aplica | Q113: Crear template canónico de 'Cierre regulatorio CNBV' que los 3 WFs adopten: (1) Propiedades completas (Historial pago, Estado crédito final, Monto recuperado, Fecha cierre); (2) Notificación por rol a Compliance + Dirección + Vian + Memo; (3) Registro CNBV trazable con todas las propiedades; (4) Tarea de archivo de expediente. WF-059 (Aprobación comité) puede inspirar. | S113: Master de Implementación Cobranza - Monific.xlsx | T113: Auditoría: Abierto; BNO validó por escrito que el hallazgo APLICA | U113: 2026-05-19 | V113: 46191 | W113: Sí
A114: CON-113 | B114: 2ª Auditoría | C114: BIT-001 | D114: Equipos | E114: Transversal | F114: Transversal | G114: ARI (FR/EM) quedó en el equipo "Legal" compartido con Compliance Monific (emiliano@monific.com), sin equipo dedicado. | H114: Crítico | I114: Crítico | J114: Abierto | K114: Compartido BNO+Monific | L114: Compartido (BNO + Monific) | N114: Sigue mal (abierto) | O114: No aplica | Q114: Crear equipo dedicado "Despacho Externo ARI" y separar a Compliance interno; revisar qué WFs/objetos notifican o comparten con "Legal". | R114: HubSpot Users&Teams: equipo "Legal" = Evelyn Montes (emontes@fulmentfi.com), FRANCISCO RODRIGUEZ (direccion@fulmentfi.com), Miguel Emiliano Chacon Lopez (emiliano@monific.com). | T114: Auditoría: Abierto | U114: 2026-06-08 00:00:00 | V114: 46191 | W114: Sí
A115: CON-114 | B115: 2ª Auditoría | C115: BIT-002 | D115: Nuevo ARI | E115: 02 Solicitante | F115: WF-016 / Solicitantes Etapa 03 Nº02 | G115: El WF "Notificación interna a involucrados" notifica al equipo "Legal" (donde hoy está ARI), exponiendo pipeline interno de Solicitantes a un despacho externo. | H115: Crítico | I115: Crítico | J115: Abierto | K115: Compartido BNO+Monific | L115: Compartido (BNO + Monific) | N115: Sigue mal (abierto) | O115: No aplica | Q115: Cambiar destinatario de "Legal" a "Evaluación Jurídica" (EEJ), que es el equipo que el master pretendía; excluir al equipo donde está ARI. | R115: Canvas flow 1808311603: "Enviar … a Marketing y Legal." Master declara "involucrados (EEJ y MKT)" (maestro fila 43). | T115: Auditoría: Abierto | U115: 2026-06-08 00:00:00 | V115: 46191 | W115: Sí
A116: CON-115 | B116: 2ª Auditoría | C116: BIT-004 | D116: Re-validación | E116: 05 Cobranza | F116: WF-050 / Cobranza Etapa 01 Nº01 | G116: WF de asignación de propietario sigue apuntando al equipo "Atención al Cliente" en vez del equipo "Cobranza". Sin cambio respecto a 1ª pasada. | H116: Crítico | I116: Crítico | J116: Sin cambio | K116: BNO – Implementación | L116: BNO | N116: Sigue mal (abierto) | O116: No aplica | Q116: Cambiar el target del round-robin al equipo "Cobranza". | R116: Canvas flow 1820379477: "Rotar … Asignar a Usuarios y equipos específicos → Atención al Cliente (2), Distribución Rotación". | T116: Auditoría: Sin cambio | U116: 2026-06-08 00:00:00 | V116: 46191 | W116: Sí
A117: CON-116 | B117: 2ª Auditoría | C117: BIT-011 | D117: Re-validación | E117: 02 Solicitante | F117: WF-008 | G117: Reinscripción desactivada: si el comité aprueba tras entrar a Evaluación (caso normal), el WF no dispara y el negocio se atora en Evaluación. | H117: Crítico | I117: Crítico | J117: Sin cambio | K117: BNO – Implementación | L117: BNO | N117: Sigue mal (abierto) | O117: No aplica | Q117: Activar reinscripción o cambiar trigger a 'Resolución de Comité cambia a Aprobado'. Probar en sandbox con decisión previa y posterior al ingreso. | R117: Flow 1807924876 'Etapa 02 Nº01 Cambio de etapa a Formalización'. Trigger: Pipeline Solicitantes + Etapa=Evaluación + Resolución de Comité=Aprobado, con 'Reinscripción desactivada' visible en canvas. | S117: Re-validación; actualiza fila 22.0 de la 1ª pasada | T117: Auditoría: Sin cambio | U117: 2026-06-09 00:00:00 | V117: 46191 | W117: Sí
A118: CON-117 | B118: 2ª Auditoría | C118: BIT-012 | D118: Re-validación | E118: 02 Solicitante | F118: WF-008 | G118: Al mover a Formalización no se escribe Fecha de cambio de etapa ni Origen del cambio. Sin trazabilidad CNBV de quién/qué movió el negocio. | H118: Crítico | I118: Crítico | J118: Sin cambio | K118: BNO – Implementación | L118: BNO | N118: Sigue mal (abierto) | O118: No aplica | Q118: Agregar acciones Editar registro: Fecha cambio etapa a Formalización y Origen=WF-008. Replicar en WF-009/015/018/022. | R118: Flow 1807924876. Única acción es '1. Editar registro' que define Pipeline y etapa=Formalización; no hay acción que escriba fecha de cambio ni origen. | S118: Re-validación; actualiza fila 23.0 de la 1ª pasada | T118: Auditoría: Sin cambio | U118: 2026-06-09 00:00:00 | V118: 46191 | W118: Sí
A119: CON-118 | B119: 2ª Auditoría | C119: BIT-014 | D119: Re-validación | E119: 02 Solicitante | F119: WF-009 | G119: Reinscripción desactivada en rechazos: si el comité rechaza tras entrar a Evaluación (caso normal), el WF no dispara y el negocio no pasa a Cierre Perdido. | H119: Crítico | I119: Crítico | J119: Sin cambio | K119: BNO – Implementación | L119: BNO | N119: Sigue mal (abierto) | O119: No aplica | Q119: Activar reinscripción o disparar por 'Resolución de Comité cambia a Rechazado'. | R119: Flow 1807927041 'Etapa 02 Nº02 Cambio de etapa a perdido'. Trigger: Evaluación + Resolución de Comité=Rechazado, 'Reinscripción desactivada' visible. | S119: Re-validación; actualiza fila 25.0 de la 1ª pasada | T119: Auditoría: Sin cambio | U119: 2026-06-09 00:00:00 | V119: 46191 | W119: Sí
A120: CON-119 | B120: 2ª Auditoría | C120: BIT-015 | D120: Re-validación | E120: 02 Solicitante | F120: WF-009 | G120: Al mover a Cierre Perdido no escribe Fecha de cambio de etapa ni Origen del cambio. Sin trazabilidad CNBV en rechazos. | H120: Crítico | I120: Crítico | J120: Sin cambio | K120: BNO – Implementación | L120: BNO | N120: Sigue mal (abierto) | O120: No aplica | Q120: Agregar acciones Editar registro: Fecha cambio etapa y Origen=WF-009. | R120: Flow 1807927041: única acción '1. Editar registro' define etapa=Cierre perdido; no escribe fecha de cambio ni origen. | S120: Re-validación; actualiza fila 26.0 de la 1ª pasada | T120: Auditoría: Sin cambio | U120: 2026-06-09 00:00:00 | V120: 46191 | W120: Sí
A121: CON-120 | B121: 2ª Auditoría | C121: BIT-016 | D121: Nuevo ARI | E121: 02 Solicitante | F121: WF-010 | G121: FUGA ARI adicional a BIT-002: la acción 1 envía notificación interna al equipo 'Legal', donde hoy está ARI (FR/EM). ARI recibe avisos del pipeline de Solicitantes en Evaluación. | H121: Crítico | I121: Crítico | J121: Abierto | K121: BNO – Implementación | L121: BNO | N121: Sigue mal (abierto) | O121: No aplica | Q121: Sacar a ARI de 'Legal' (equipo dedicado) o cambiar destinatario a equipo interno de Compliance. Mismo arreglo que BIT-002. | R121: Flow 1808160659 'Etapa 02 Nº03 Correo interno a involucrados'. Acción 1: 'Enviar notificación interna por correo... a Legal'. Equipo Legal contiene a ARI (Fulmentfi). | T121: Auditoría: Abierto | U121: 2026-06-09 00:00:00 | V121: 46191 | W121: Sí
A122: CON-121 | B122: 2ª Auditoría | C122: BIT-017 | D122: Re-validación | E122: 02 Solicitante | F122: WF-010 | G122: Acción 4 'Enviar correo Notificacion al DG' va a 'Todos los contactos asociados', lo que incluye al solicitante. Filtración de comunicación interna al cliente. | H122: Crítico | I122: Crítico | J122: Sin cambio | K122: BNO – Implementación | L122: BNO | N122: Sigue mal (abierto) | O122: No aplica | Q122: Cambiar destinatario a un usuario/rol interno (DG) en vez de 'Todos los contactos asociados'. Es notificación interna, no debe ir al cliente. | R122: Flow 1808160659, acción 4: 'Enviar Notificacion al DG de avance de solicitante a los contactos asociados con la etiqueta Todos los contactos asociados'. | S122: Re-validación; actualiza fila 27.0 de la 1ª pasada | T122: Auditoría: Sin cambio | U122: 2026-06-09 00:00:00 | V122: 46191 | W122: Sí
A123: CON-122 | B123: 2ª Auditoría | C123: BIT-020 | D123: Re-validación | E123: 02 Solicitante | F123: WF-012 | G123: Trigger solo dispara si Resolución=Aprobado y reinscripción desactivada. En rechazos o si la decisión se setea tras el ingreso, la Fecha de decisión nunca se registra. Rompe SLA/trazabilidad. | H123: Crítico | I123: Crítico | J123: Sin cambio | K123: BNO – Implementación | L123: BNO | N123: Sigue mal (abierto) | O123: No aplica | Q123: Disparar por 'Resolución de Comité cambia' (Aprobado o Rechazado) y activar reinscripción, para registrar fecha en todos los casos. | R123: Flow 1807992844 'Etapa 02 Nº05 fijar Fecha de decisión del comité'. Trigger: Evaluación + Resolución=Aprobado, 'Reinscripción desactivada'. Acción: define fecha=fecha de ejecución. | S123: Re-validación; actualiza fila 32.0 de la 1ª pasada | T123: Auditoría: Sin cambio | U123: 2026-06-09 00:00:00 | V123: 46191 | W123: Sí
A124: CON-123 | B124: 2ª Auditoría | C124: BIT-021 | D124: Re-validación | E124: 02 Solicitante | F124: WF-013 | G124: Trigger solo Resolución=Aprobado con reinscripción desactivada. Si la decisión se setea tras el ingreso a Evaluación, la tarea de carta de aceptación nunca se crea. | H124: Crítico | I124: Crítico | J124: Sin cambio | K124: BNO – Implementación | L124: BNO | N124: Sigue mal (abierto) | O124: No aplica | Q124: Disparar por cambio de propiedad Resolución=Aprobado y activar reinscripción. | R124: Flow 1807930283 'Etapa 02 Nº06 Crear tarea carta de aceptación'. Trigger: Evaluación + Resolución=Aprobado, 'Reinscripción desactivada'. | S124: Re-validación; actualiza fila 35.0 de la 1ª pasada | T124: Auditoría: Sin cambio | U124: 2026-06-09 00:00:00 | V124: 46191 | W124: Sí
A125: CON-124 | B125: 2ª Auditoría | C125: BIT-023 | D125: Re-validación | E125: 02 Solicitante | F125: WF-014 | G125: WF DESACTIVADO en HubSpot (master dice 'Encendido'). Las solicitudes rechazadas no generan tarea de carta de rechazo; el solicitante nunca recibe notificación formal. | H125: Crítico | I125: Crítico | J125: Sin cambio | K125: BNO – Implementación | L125: BNO | N125: Sigue mal (abierto) | O125: No aplica | Q125: Decidir si debe activarse; si sí, corregir trigger (cambio de propiedad) y reinscripción antes de activar. Alinear con master. | R125: Flow 1808048197 'Etapa 02 Nº07 Crear tarea carta de rechazo'. Badge 'DESACTIVADA'; botón 'Revisar y activar'. Trigger: Evaluación + Resolución=Rechazado. | S125: Re-validación; actualiza fila 38.0 de la 1ª pasada | T125: Auditoría: Sin cambio | U125: 2026-06-09 00:00:00 | V125: 46191 | W125: Sí
A126: CON-125 | B126: 2ª Auditoría | C126: BIT-024 | D126: Re-validación | E126: 02 Solicitante | F126: WF-015 | G126: Pasa a Proceso de firma sin escribir Fecha de cambio etapa ni Origen; reinscripción desactivada (si Estatus=Liquidada se setea en la etapa, el WF no dispara). Etapa crítica de firma. | H126: Crítico | I126: Crítico | J126: Sin cambio | K126: BNO – Implementación | L126: BNO | N126: Sigue mal (abierto) | O126: No aplica | Q126: Agregar escritura de Fecha cambio etapa + Origen=WF-015 y disparar por cambio de propiedad; activar reinscripción. | R126: Flow 1808166282 'Etapa 03 Nº01 Cambio a proceso de firma'. Trigger: Formalización + Estatus de formalización=Liquidada, 'Reinscripción desactivada'. Única acción: edita etapa. | S126: Re-validación; actualiza fila 41.0 de la 1ª pasada | T126: Auditoría: Sin cambio | U126: 2026-06-09 00:00:00 | V126: 46191 | W126: Sí
A127: CON-126 | B127: 2ª Auditoría | C127: BIT-026 | D127: Nuevo ARI | E127: 02 Solicitante | F127: WF-016 / Solicitantes Etapa 03 Nº02 | G127: Ampliación de BIT-002: confirmado en canvas que la única acción notifica 'a Marketing y Legal'. ARI (en equipo Legal) sigue recibiendo el aviso de inicio de gestiones. No duplicar BIT-002. | H127: Crítico | I127: Crítico | J127: Sin cambio | K127: BNO – Implementación | L127: BNO | N127: Sigue mal (abierto) | O127: No aplica | Q127: Mismo arreglo que BIT-002: sacar a ARI de 'Legal' o redirigir a equipo interno. Decidir corte inmediato vs esperar arreglo BNO. | R127: Flow 1808311603 'Etapa 03 Nº02 Notificación interna a involucrados'. Acción 1: 'Enviar Inicio de gestiones internas... a Marketing y Legal'. Confirma BIT-002. | T127: Auditoría: Sin cambio | U127: 2026-06-09 00:00:00 | V127: 46191 | W127: Sí
A128: CON-127 | B128: 2ª Auditoría | C128: BIT-027 | D128: Re-validación | E128: 02 Solicitante | F128: WF-017 | G128: El escalamiento por formalización estancada (>2 días) se envía al mismo 'Propietario del negocio' que está estancado, no a un superior. El escalamiento no cumple su propósito. | H128: Crítico | I128: Crítico | J128: Sin cambio | K128: BNO – Implementación | L128: BNO | N128: Sigue mal (abierto) | O128: No aplica | Q128: Redirigir escalamiento a rol superior (jefe de Formalización), no al propietario estancado. | R128: Flow 1808313453 'Etapa 03 Nº03 Notificación interna a superior estancado'. Acción 1: 'Atender escalamiento por formalización pendiente a Propietario del negocio'. | S128: Re-validación; actualiza fila 46.0 de la 1ª pasada | T128: Auditoría: Sin cambio | U128: 2026-06-09 00:00:00 | V128: 46191 | W128: Sí
A129: CON-128 | B129: 2ª Auditoría | C129: BIT-030 | D129: Re-validación | E129: 02 Solicitante | F129: WF-018 | G129: Al pasar a Cierre Ganado no escribe Fecha de cambio de etapa ni Origen. Mismo gap de trazabilidad CNBV que WF-008/009/015. WF-018 no estaba auditado en el maestro. | H129: Crítico | I129: Crítico | J129: Abierto | K129: BNO – Implementación | L129: BNO | N129: Sigue mal (abierto) | O129: No aplica | Q129: Agregar Editar registro: Fecha cambio etapa a Ganado y Origen=WF-018. | R129: Flow 1808711272: acciones son '1. Editar registro' (etapa a Ganado) y '2. notificación'. Ninguna escribe Fecha de cambio ni Origen. | T129: Auditoría: Abierto | U129: 2026-06-09 00:00:00 | V129: 46191 | W129: Sí
A130: CON-129 | B130: 2ª Auditoría | C130: BIT-032 | D130: Re-validación | E130: 02 Solicitante | F130: WF-020 | G130: WF DESACTIVADO (master lo marca 'Implementado'). La cadena WF-019->WF-020 queda rota: se setea la bandera pero la secuencia de firma nunca se envía al solicitante. | H130: Crítico | I130: Crítico | J130: Sin cambio | K130: Monific – Raquel | L130: Monific – negocio (Raquel) | N130: Sigue mal (abierto) | O130: No aplica | Q130: Validar el correo de la secuencia y activar el WF. Decisión de Raquel sobre contenido. | R130: Flow 1808682771 'Etapa 04 Nº03 Enviar secuencia'. Badge 'DESACTIVADA'. Trigger: contactos con 'Inscribir en secuencia de firma=Sí'; inscribe en secuencia 'WF - Notificar aprobación de credito firma'. | S130: Re-validación; actualiza fila 51.0 de la 1ª pasada | T130: Auditoría: Sin cambio | U130: 2026-06-09 00:00:00 | V130: 46191 | W130: No
A131: CON-130 | B131: 2ª Auditoría | C131: BIT-035 | D131: Re-validación | E131: 02 Solicitante | F131: WF-022 | G131: Mueve a Cierre Perdido sin setear 'Razón de cierre perdido', sin crear tarea para documentar/subir carta, y sin Fecha de cambio etapa ni Origen. | H131: Crítico | I131: Crítico | J131: Sin cambio | K131: BNO – Implementación | L131: BNO | N131: Sigue mal (abierto) | O131: No aplica | Q131: Agregar: setear Razón de cierre perdido, crear tarea de documentación y escribir Fecha cambio etapa + Origen=WF-022. | R131: Flow 1808890501: única acción '1. Editar registro' define etapa=Cierre perdido; sin razón de cierre, sin tarea, sin fecha/origen. | S131: Re-validación; actualiza fila 54.0 de la 1ª pasada | T131: Auditoría: Sin cambio | U131: 2026-06-09 00:00:00 | V131: 46191 | W131: Sí
A132: CON-131 | B132: 2ª Auditoría | C132: BIT-037 | D132: Re-validación | E132: 02 Solicitante | F132: WF-024 | G132: BUG CONFIRMADO: el WF 'Establecer propiedades de perdido' tiene trigger Etapa=Cierre GANADO (debería ser Perdido). Además define Fecha de cierre. Se dispara en ganados, no en perdidos. | H132: Crítico | I132: Crítico | J132: Sin cambio | K132: BNO – Implementación | L132: BNO | N132: Sigue mal (abierto) | O132: No aplica | Q132: Corregir trigger a Etapa=Cierre perdido y revisar que las propiedades correspondan a perdido (no Fecha de cierre). | R132: Flow 1808747845 'Etapa 06: Perdido Nº01 Establecer propiedades de perdido'. Trigger: 'Etapa del negocio es cualquiera de Cierre ganado'. Acción 1 define Fecha de cierre. | S132: Re-validación; actualiza fila 56.0 de la 1ª pasada | T132: Auditoría: Sin cambio | U132: 2026-06-09 00:00:00 | V132: 46191 | W132: Sí
A133: CON-132 | B133: 2ª Auditoría | C133: BIT-041 | D133: Re-validación | E133: 01 Inversionista | F133: WF-026 | G133: BUG copy-paste de WF-025: el flow 'Cambio de etapa a congelado' en realidad mueve el negocio a Inversionista Activo. Nunca congela. | H133: Crítico | I133: Crítico | J133: Sin cambio | K133: BNO – Implementación | L133: BNO | N133: Sigue mal (abierto) | O133: No aplica | Q133: Corregir acción para que defina la etapa como Congelado, no Activo. | R133: Flow 1808819073 'Perfil Nº02 Cambio de etapa a congelado'. Trigger: Perfil Activo + >15 días. Acción '1. Editar registro: Define etapa como Inversionista Activo' (debería ser Congelado). | T133: Auditoría: Sin cambio | U133: 2026-06-09 00:00:00 | V133: 46191 | W133: Sí
A134: CON-133 | B134: 2ª Auditoría | C134: BIT-042 | D134: Re-validación | E134: 01 Inversionista | F134: WF-027 | G134: CLABE STP hardcodeada al literal '1'. El dato financiero (CLABE 18 dígitos de STP) debe venir de Admin.Monific, no fijarse en 1. | H134: Crítico | I134: Crítico | J134: Sin cambio | K134: Monific – Tech (Jesús) | L134: Monific – TI | N134: Sigue mal (abierto) | O134: No aplica | Q134: Reemplazar el valor fijo por integración que traiga la CLABE STP real del inversionista desde Admin.Monific. | R134: Flow 1808747892 'Perfil Nº03 Actualizar propiedades de negocio'. Acción '2. Editar registro: Define CLABE STP como 1'. | T134: Auditoría: Sin cambio | U134: 2026-06-09 00:00:00 | V134: 46191 | W134: No
A135: CON-134 | B135: 2ª Auditoría | C135: BIT-051 | D135: Re-validación | E135: 01 Inversionista | F135: WF-033 | G135: Monto de primera inversión hardcodeado a 0. Dato financiero clave queda en cero fijo, no toma el monto real invertido. Riesgo CNBV de integridad de datos. | H135: Crítico | I135: Crítico | J135: Sin cambio | K135: Monific – Tech (Jesús) | L135: Monific – TI | N135: Sigue mal (abierto) | O135: No aplica | Q135: Tomar el monto real de la primera inversión desde Admin.Monific en vez de fijar 0. | R135: Flow 1808890885. Acción '2. Editar registro: Define Monto de primera inversión como 0'. | T135: Auditoría: Sin cambio | U135: 2026-06-09 00:00:00 | V135: 46191 | W135: No
A136: CON-135 | B136: 2ª Auditoría | C136: BIT-053 | D136: Re-validación | E136: 01 Inversionista | F136: WF-034 | G136: Tokens sin resolver: la acción de inscribir en secuencia usa {{ sequenceId }} y {{ senderType }} literales. HubSpot marca 'Se necesitan cambios'. El flow nunca funcionará. | H136: Crítico | I136: Crítico | J136: Sin cambio | K136: Monific – Tech (Jesús) | L136: Monific – TI | N136: Sigue mal (abierto) | O136: No aplica | Q136: Configurar secuencia real y remitente; eliminar tokens sin resolver. | R136: Flow 1808851292 'Activo Nº04 Realizar envio de secuencia'. Nodo '1. Inscribirse en una secuencia: Se necesitan cambios - Inscribir al contacto en {{ sequenceId }} de {{ senderType }}'. | T136: Auditoría: Sin cambio | U136: 2026-06-09 00:00:00 | V136: 46191 | W136: No
A137: CON-136 | B137: 2ª Auditoría | C137: BIT-059 | D137: Re-validación | E137: 01 Inversionista | F137: WF-039 | G137: BUG: en vez de notificar el cierre, el flow REGRESA el negocio de Cierre a Inversionista Activo (define etapa 1341314730). Corrompe el journey y no envía ninguna notificación. | H137: Crítico | I137: Crítico | J137: Sin cambio | K137: BNO – Implementación | L137: BNO | N137: Sigue mal (abierto) | O137: No aplica | Q137: Reemplazar la acción de cambio de etapa por la notificación interna prevista; no revertir el cierre. | R137: Flow 1808890376 'Cierre Nº01 Notificaciones internas'. Trigger Etapa=1341314732 (Cierre). Acción '1. Editar registro: define etapa como 1341314730' (= Inversionista Activo). | T137: Auditoría: Sin cambio | U137: 2026-06-09 00:00:00 | V137: 46191 | W137: Sí
A138: CON-137 | B138: 2ª Auditoría | C138: BIT-070 | D138: Re-validación | E138: 04 ATC | F138: WF-045 | G138: WF sigue DESACTIVADO y sin acciones (Trigger -> Fin). No crea la tarea automatica Tipo C a Guillermo con SLA que pide la minuta marzo 2026. | H138: Crítico | I138: Crítico | J138: Sin cambio | K138: BNO – Implementación | L138: BNO | N138: Sigue mal (abierto) | O138: No aplica | Q138: Construir accion: crear tarea a Guillermo con SLA (1h) y setear Fecha escalamiento Tipo C; luego activar el WF. | R138: Flow ID 1822136840. DESACTIVADA (boton 'Revisar y activar'). Trigger Grupo 1: Estado del ticket = En atencion (Servicio al Cliente) Y Tipo de ticket = Solicitante. Cuerpo: ninguna accion, va directo a 'Fin'. | S138: Re-validación; actualiza fila 96 de la 1ª pasada | T138: Auditoría: Sin cambio | U138: 2026-06-09 | V138: 46191 | W138: Sí
A139: CON-138 | B139: 2ª Auditoría | C139: BIT-076 | D139: Re-validación | E139: 04 ATC | F139: WF-049 | G139: El cierre dispara solo con Estado=Cerrado, sin validacion previa (confirmacion de cliente, nota de resolucion ni validacion de superior). Cualquier cierre manual lo activa. | H139: Crítico | I139: Crítico | J139: Sin cambio | K139: BNO – Implementación | L139: BNO | N139: Sigue mal (abierto) | O139: No aplica | Q139: Agregar condiciones de cierre valido (nota de resolucion obligatoria, confirmacion de cliente) antes de permitir el cierre. | R139: Flow ID 1822136625. Trigger Grupo 1 unica condicion: 'Estado del ticket es cualquiera de Cerrado (Servicio al Cliente)'. Accion 1: Define Fecha de cierre = fecha de ejecucion. WF Activado. | S139: Re-validación; actualiza fila 100 de la 1ª pasada | T139: Auditoría: Sin cambio | U139: 2026-06-09 | V139: 46191 | W139: Sí
...

Sheet Comunicaciones (81)
A1: ID | B1: Área | C1: Comunicación | D1: Canal | E1: Trigger | F1: Destinatario | G1: Responsable | H1: Responsable BNO | I1: Propiedad | J1: Tokens | K1: Estado objetivo | L1: Estado de implementación | M1: % avance | N1: Fecha objetivo | O1: Validación Monific (Raquel) | P1: Link al asset HubSpot | Q1: Notas / Bloqueos
A2: SOL-001 | B2: Solicitantes | C2: Confirmación de solicitud recibida | D2: Email | E2: Formulario / negocio nuevo | F2: Solicitante | G2: A.A.S. | I2: PB-SOL-NEW | J2: TK-BASE + TK-SOL | K2: Crear | L2: No iniciado | M2: 0.0 | O2: Pendiente
A3: SOL-002 | B3: Solicitantes | C3: Solicitud de documentación inicial | D3: Email | E3: Califica pre-revisión | F3: Solicitante | G3: A.A.S. | I3: PB-SOL-NEW | J3: TK-BASE + TK-SOL | K3: Crear | L3: No iniciado | M3: 0.0 | O3: Pendiente
A4: SOL-003 | B4: Solicitantes | C4: Recordatorio documentación día 3 | D4: Email | E4: 3 días sin carga completa | F4: Solicitante | G4: A.A.S. | I4: PB-SOL-NEW | J4: TK-BASE + TK-SOL | K4: Crear | L4: No iniciado | M4: 0.0 | O4: Pendiente
A5: SOL-004 | B5: Solicitantes | C5: Recordatorio documentación día 6 | D5: Email | E5: 6 días sin carga completa | F5: Solicitante | G5: A.A.S. | I5: PB-SOL-NEW | J5: TK-BASE + TK-SOL | K5: Crear | L5: No iniciado | M5: 0.0 | O5: Pendiente
A6: SOL-005 | B6: Solicitantes | C6: No show o sin respuesta | D6: Email | E6: Cita vencida o 7 días sin respuesta | F6: Solicitante | G6: A.A.S. | I6: PB-SOL-NEW | J6: TK-BASE + TK-SOL | K6: Crear | L6: No iniciado | M6: 0.0 | O6: Pendiente
A7: SOL-006 | B7: Solicitantes | C7: Dudas sobre requisitos | D7: Email | E7: Solicitante pide orientación | F7: Solicitante | G7: A.A.S. | I7: PB-SOL-NEW | J7: TK-BASE + TK-SOL | K7: Crear | L7: No iniciado | M7: 0.0 | O7: Pendiente
A8: SOL-007 | B8: Solicitantes | C8: Pausa voluntaria | D8: Email | E8: Solicitante decide pausar | F8: Solicitante | G8: A.A.S. | I8: PB-SOL-NEW | J8: TK-BASE + TK-SOL | K8: Crear | L8: No iniciado | M8: 0.0 | O8: Pendiente
A9: SOL-008 | B9: Solicitantes | C9: Carpeta Drive creada | D9: WhatsApp | E9: Carpeta de expediente creada | F9: Solicitante | G9: A.A.S. | I9: PB-SOL-NEW | J9: TK-BASE + TK-SOL | K9: Crear | L9: No iniciado | M9: 0.0 | O9: Pendiente
A10: SOL-009 | B10: Solicitantes | C10: Expediente completo | D10: Email | E10: Validación documental completa | F10: Solicitante | G10: A.A.S. | I10: PB-SOL-NEW | J10: TK-BASE + TK-SOL | K10: Crear | L10: No iniciado | M10: 0.0 | O10: Pendiente
A11: SOL-010 | B11: Solicitantes | C11: Expediente con observaciones | D11: Email | E11: Validación documental parcial | F11: Solicitante | G11: A.A.S. | I11: PB-SOL-NEW | J11: TK-BASE + TK-SOL | K11: Crear | L11: No iniciado | M11: 0.0 | O11: Pendiente
A12: SOL-011 | B12: Solicitantes | C12: No viable documental | D12: Email | E12: Documentación no subsanable | F12: Solicitante | G12: A.A.S. | I12: PB-SOL-NEW | J12: TK-BASE + TK-SOL | K12: Crear | L12: No iniciado | M12: 0.0 | O12: Pendiente
A13: SOL-012 | B13: Solicitantes | C13: Avance a evaluación financiera | D13: Email | E13: Pasa a análisis financiero | F13: Solicitante | G13: A.A.S. | I13: PB-SOL-NEW | J13: TK-BASE + TK-SOL | K13: Crear | L13: No iniciado | M13: 0.0 | O13: Pendiente
... A82: PDF-004 | B82: PDF institucional | C82: Carta de refinanciamiento | D82: PDF | E82: Reestructura aprobada | F82: Solicitante | G82: Legal / Owner de pipeline | I82: PB-COB-REFI | J82: TK-BASE + TK-COB + TK-PDF | K82: Crear | L82: No iniciado | M82: 0.0 | O82: Pendiente
B84: NOTA: el TEXTO/COPY de cada comunicación (asunto + cuerpo + tokens) está en el documento «Matriz completa de comunicación» — Parte II (Biblioteca de plantillas y textos). Esta hoja lleva el control de implementación; el contenido para pegar vive en ese anexo.

Sheet WF estado real (96)
A1: # | B1: Workflow (nombre real en HubSpot) | C1: Estado | D1: Validación Monific (Raquel) | E1: Creado | F1: Últ. modificación
A2: 1 | B2: WF | Form: Inversionista | C2: OFF | D2: Sigue mal (apagado) | E2: 2025-03-14 | F2: 2025-07-02
A3: 2 | B3: WF | Notificaciones de cobro | C3: OFF | D3: Sigue mal (apagado) | E3: 2025-03-24 | F3: 2025-04-28
A4: 3 | B4: El pipeline es "Solicitud de financiamiento", la etapa es "Publicación" | C4: OFF | D4: Sigue mal (apagado) | E4: 2025-04-07 | F4: 2025-07-25
A5: 4 | B5: Seguimiento de encuesta personalizada 4 - Detractor | C5: OFF | D5: Sigue mal (apagado) | E5: 2025-04-21 | F5: 2025-04-21
A6: 5 | B6: El pipeline es "inversión", la etapa es "Depósito" | C6: OFF | D6: Sigue mal (apagado) | E6: 2025-04-28 | F6: 2025-04-28
A7: 6 | B7: Asignación de propietario | Contactos sin | C7: OFF | D7: Sigue mal (apagado) | E7: 2025-05-21 | F7: 2025-08-12
A8: 7 | B8: Campañas Meta | Asignación | C8: OFF | D8: Sigue mal (apagado) | E8: 2025-06-03 | F8: 2025-06-03
A9: 8 | B9: Creación de lead | Inversionistas | C9: OFF | D9: Sigue mal (apagado) | E9: 2025-06-18 | F9: 2025-06-18
A10: 9 | B10: El pipeline es "Inversionistas", la etapa es "Inversión activa" | C10: OFF | D10: Sigue mal (apagado) | E10: 2025-06-18 | F10: 2025-06-18
A11: 10 | B11: WF | Notificaciones de cobro ACTUALIZADO | C11: OFF | D11: Sigue mal (apagado) | E11: 2025-06-18 | F11: 2025-07-22
A12: 11 | B12: Recordatorio pago de préstamo general | SOLICITUDES | C12: OFF | D12: Sigue mal (apagado) | E12: 2025-06-25 | F12: 2025-06-25
A13: 12 | B13: MODELO Notificaciones de cobro | Tickets | C13: OFF | D13: Sigue mal (apagado) | E13: 2025-06-30 | F13: 2025-07-03
... A97: 96 | B97: 01. Contactos | 01. Datos | Nº 01 | Crear negocio de solicitante o inversionistas | V1 | C97: ON | D97: Validado (activo) | E97: 2026-06-05 | F97: 2026-06-08
B99: Nota: «Validado (activo)» = el workflow está ENCENDIDO al 17-jun-2026; NO certifica que la lógica interna (nodos, correos, tokens) sea correcta — eso se valida abriendo el flow. «Sigue mal (apagado)» = desactivado. Ajusta cada fila con el menú si revisas la lógica.

Sheet WF lógica (detalle API)
A1: # | B1: Workflow | C1: Estado | D1: Nodos | E1: ¿Envía correo? | F1: Solo set_property (no comunica) | G1: ¿Secuencia? | H1: Token texto plano | I1: ¿Notifica a BNO (Ochoa)?
A2: 1 | B2: 01. Contactos | 01. Datos | Nº 01 | Crear negocio de solicitante o inversionistas | V1 | C2: True | D2: 60 | E2: No | F2: Sí | G2: No | H2: Sí | I2: No
A3: 2 | B3: 03. Negocios | 01. Solicitantes | Etapa 01: Nuevo | Nº 01 | Cambio de etapa a Evaluación | V1 | C3: True | D3: 3 | E3: No | F3: Sí | G3: No | H3: No | I3: No
A4: 3 | B4: 03. Negocios | 01. Solicitantes | Etapa 01: Nuevo | Nº 02 | Tarea de creación de drive | V1 | C4: True | D4: 21 | E4: No | F4: Sí | G4: No | H4: Sí | I4: No
A5: 4 | B5: 03. Negocios | 01. Solicitantes | Etapa 01: Nuevo | Nº 03 | Actualizar estatus y enviar secuencia | V1 | C5: True | D5: 20 | E5: No | F5: Sí | G5: Sí | H5: Sí | I5: No
A6: 5 | B6: 03. Negocios | 01. Solicitantes | Etapa 01: Nuevo | Nº 04 | Enviar secuencia desde contacto + 15 días | V1 | C6: False | D6: 17 | E6: No | F6: Sí | G6: Sí | H6: Sí | I6: No
A7: 6 | B7: 03. Negocios | 01. Solicitantes | Etapa 01: Nuevo | Nº 05 | Enviar a solicitante requerimiento de su documentación | V1 | C7: True | D7: 4 | E7: No | F7: Sí | G7: No | H7: No | I7: No
A8: 7 | B8: 03. Negocios | 01. Solicitantes | Etapa 01: Nuevo | Nº 07 | Enviar secuencia desde contacto + 2 días | V1 | C8: False | D8: 17 | E8: No | F8: Sí | G8: Sí | H8: Sí | I8: No
A9: 8 | B9: 03. Negocios | 01. Solicitantes | Etapa 01: Nuevo | Nº 08 | Enviar secuencia Post formulario | V1 | C9: False | D9: 13 | E9: No | F9: Sí | G9: Sí | H9: Sí | I9: No
A10: 9 | B10: 03. Negocios | 01. Solicitantes | Etapa 02: Evaluación | Nº 01 | Cambio de etapa a Formalización | V1 | C10: True | D10: 3 | E10: No | F10: Sí | G10: No | H10: No | I10: No
A11: 10 | B11: 03. Negocios | 01. Solicitantes | Etapa 02: Evaluación | Nº 02 | Cambio de etapa a perdido | V1 | C11: True | D11: 3 | E11: No | F11: Sí | G11: No | H11: No | I11: No
A12: 11 | B12: 03. Negocios | 01. Solicitantes | Etapa 02: Evaluación | Nº 05 | fijar la propiedad "Fecha de decisión del comité" | V1 | C12: True | D12: 3 | E12: No | F12: Sí | G12: No | H12: No | I12: No
A13: 12 | B13: 03. Negocios | 01. Solicitantes | Etapa 02: Evaluación | Nº 06 | Crear tarea de la carta de aceptación | V1 | C13: True | D13: 9 | E13: No | F13: Sí | G13: No | H13: Sí | I13: No
... A97: 96 | B97: WF | Form: Solicitud de financiamiento | C97: True | D97: 110 | E97: Sí | F97: No | G97: No | H97: Sí | I97: No
B99: Resumen: de 96 workflows, 9 envían correo y 85 solo hacen set_property sin comunicar. 26 nodos inscriben a secuencia SIN sequenceId. 701 nodos con token en texto plano. 21 nodos de notificación interna, 3 a David Ochoa (BNO).
B101: Nodos de notificación interna a David Ochoa (BNO) — actionTypeId 0-8:
B102: • 03. Negocios | 01. Solicitantes | Etapa 02: Evaluación | Nº 04 | Correo interno a DG | V1 | C102: → asunto: | D102: Nuevo solicitante enviado a evaluación
B103: • 03. Negocios | 01. Solicitantes | Etapa 03: Formalización | Nº 03 | Notificación interna a superior estancado | V1 | C103: → asunto: | D103: Escalamiento por apoyo en formalización
B104: • 03. Negocios | 01. Solicitantes | Etapa 04: Proceso de firma | Nº 01 | Cambio de etapa a ganado | V1 | C104: → asunto: | D104: Solicitud de publicación de campaña en Monific

Sheet Verificación 31 propiedades
A1: # | B1: ID | C1: Área | D1: Etiqueta | E1: Nombre interno sugerido | F1: Objeto | G1: Prioridad | H1: Resultado (API 17-jun) | I1: Detalle
A2: 1 | B2: NEW-PROP-001 | C2: Comercial | D2: Tipo de cliente | E2: tipo_de_cliente | F2: Deal | G2: P1 | H2: EXISTE | I2: creada 2025-03-17 (userId 11260213)
A3: 2 | B3: NEW-PROP-002 | C3: Comercial | D3: Canal de entrada | E3: canal_de_entrada | F3: Contact | G3: P1 | H3: EXISTE (por etiqueta) | I3: coincide por etiqueta, nombre interno distinto
A4: 3 | B4: NEW-PROP-003 | C4: Comercial | D4: Fuente de Lead | E4: fuente_de_lead | F4: Contact | G4: P1 | H4: EXISTE (por etiqueta) | I4: coincide por etiqueta, nombre interno distinto
A5: 4 | B5: NEW-PROP-004 | C5: Comercial | D5: Nombre de Broker | E5: nombre_de_broker | F5: Contact | G5: P2 | H5: EXISTE (por etiqueta) | I5: coincide por etiqueta, nombre interno distinto
A6: 5 | B6: NEW-PROP-005 | C6: Servicio | D6: Fecha y hora de atención del ticket | E6: fecha_y_hora_de_atencion_del_ticket | F6: Ticket | G6: P1 | H6: NO EXISTE | I6: no encontrada por nombre ni etiqueta al 17-jun-2026
A7: 6 | B7: NEW-PROP-006 | C7: Cobranza | D7: ID Campaña | E7: id_campana | F7: Custom Object (Cobranza) — confirmar con BNO | G7: P1 | H7: NO EXISTE | I7: no encontrada por nombre ni etiqueta al 17-jun-2026
A8: 7 | B8: NEW-PROP-007 | C8: Cobranza | D8: Propietario de campaña | E8: propietario_de_campana | F8: Custom Object (Cobranza) — confirmar con BNO | G8: P1 | H8: NO EXISTE | I8: no encontrada por nombre ni etiqueta al 17-jun-2026
A9: 8 | B9: NEW-PROP-008 | C9: Cobranza | D9: Link de expediente en Drive | E9: link_de_expediente_en_drive | F9: Custom Object (Cobranza) — confirmar con BNO | G9: P2 | H9: NO EXISTE | I9: no encontrada por nombre ni etiqueta al 17-jun-2026
A10: 9 | B10: NEW-PROP-009 | C10: Cobranza | D10: Condiciones especiales del proyecto | E10: condiciones_especiales_del_proyecto | F10: Custom Object (Cobranza) — confirmar con BNO | G10: P2 | H10: NO EXISTE | I10: no encontrada por nombre ni etiqueta al 17-jun-2026
A11: 10 | B11: NEW-PROP-010 | C11: Cobranza | D11: Nota de acuerdo de pago | E11: nota_de_acuerdo_de_pago | F11: Custom Object (Cobranza) — confirmar con BNO | G11: P1 | H11: NO EXISTE | I11: no encontrada por nombre ni etiqueta al 17-jun-2026
A12: 11 | B12: NEW-PROP-011 | C12: Cobranza | D12: Número de intentos de contacto | E12: numero_de_intentos_de_contacto | F12: Custom Object (Cobranza) — confirmar con BNO | G12: P2 | H12: NO EXISTE | I12: no encontrada por nombre ni etiqueta al 17-jun-2026
... A32: 31 | B32: NEW-PROP-031 | C32: Cobranza | D32: Observaciones del proceso legal | E32: observaciones_del_proceso_legal | F32: Custom Object (Cobranza) — confirmar con BNO | G32: P2 | H32: NO EXISTE | I32: no encontrada por nombre ni etiqueta al 17-jun-2026

Sheet Auditoría API 17-jun
B1: Auditoría técnica por API privada — estado real de HubSpot
B2: Extracción de SOLO LECTURA (no modifica HubSpot) · 17-jun-2026 10:06
B4: Metadata de la extracción
B5: Hub ID | C5: 48427391
B6: App ID (extractor) | C6: 42961396
B7: Scopes | C7: 33
B8: Endpoints exitosos / con error | C8: 28 / 5
B9: Workflows detectados | C9: 96
B10: Propiedades detectadas | C10: 2142
B12: Hechos verificados (evidencia objetiva)
B13: Workflows APAGADOS (de 96) | C13: 39 ← ON: 57
B14: Propiedades de las 31 de BNO que NO existen | C14: 26 de 31 (existen: 5)
B15: · por nombre interno exacto, existen solo | C15: 2 de 31
B17: Cómo se usa esto
B18: Es la 'verdad de campo' fechada que respalda los hallazgos: ver pestañas «WF estado real (96)» y «Verificación 31 propiedades». El archivo crudo completo (2,142 propiedades, JSON por endpoint) es el Excel maestro de la extracción, que se conserva como anexo de evidencia.
B20: Hallazgos adicionales verificados (2ª pasada, 17-jun)
B21: Custom objects en el portal | C21: 0 → el objeto de Cobranza NO existe
B22: Usuarios con acceso al portal | C22: 17 (6 BNO + 2 externos + Monific)
B23: · Usuarios de Black & Orange (proveedor) aún activos | C23: 6
B24: · Abogados externos (fulmentfi.com) con acceso de usuario y owner | C24: 2
B25: Pipelines de negocios | C25: 5 — sin «Mercado Secundario» ni «UNE»
B26: Equipos (teams) | C26: 15 — sin equipo dedicado para ARI
B28: Limitaciones de la extracción
B29: Secuencias (sequences): no se pudieron extraer (error de API) → los hallazgos de secuencias de cobranza NO quedan verificados por API.
B30: «posibles_duplicados» (1,725): casi todos son propiedades NATIVAS de HubSpot con nombres parecidos; no es evidencia sólida salvo casos puntuales.
B31: 60 marketing emails existen, pero NO equivalen a las 81 comunicaciones transaccionales del alcance.
B33: Reconciliación de propiedades (Matriz de masters vs estado real)
B34: Propiedades esperadas por los masters | C34: 177
B35: Encontradas en HubSpot (por etiqueta exacta) | C35: 128
B36: No encontradas en HubSpot | C36: 31 (candidatas a crear)
B37: De las existentes 'accionables', con 0% de llenado | C37: 35 (creadas pero vacías)
B39: Atribución: quién creó la configuración (propiedades 2025-2026)
B40: Creadas por Black & Orange (proveedor) | C40: 135 (Ochoa 76 · Bersot 59)
B41: Creadas por Monific | C41: 20
B42: Sin atribución a usuario actual (legacy/sistema/desactivados) | C42: 643
B43: Formularios en el portal | C43: 3
B45: Limitación clave de esta extracción
B46: El extractor obtuvo la LISTA de workflows (estado ON/OFF), NO el detalle interno de cada flow (nodos, destinatarios, tokens, sequenceId). Por eso los hallazgos de lógica interna (notifica a Ochoa/Bersot, set_property sin correo, secuencia sin sequenceId, UNE sin folio) se sostienen en las auditorías manuales, no en esta API.
B48: Lógica de workflows — VERIFICADA por API (17-jun 11:02, 4,848 nodos)
B49: Workflows que envían correo al cliente | C49: 9 de 96
...

Sheet Acceso y config (API)
B1: Acceso y configuración — estado real (API 17-jun-2026)
B3: Usuarios con acceso al portal (17)
B4: Email | C4: Nombre | D4: Dominio | E4: Clasificación
